Workbook

Sheet Sales
A1: sale_id | B1: date | C1: branch_id | D1: customer_id | E1: product_id | F1: quantity | G1: price | H1: discount | I1: total_amount
A2: 1 | B2: 2023-02-12 | C2: 5 | D2: 189 | E2: 97 | F2: 2 | G2: 158.26 | H2: 0 | I2: 316.52
A3: 2 | B3: 2023-03-24 | C3: 3 | D3: 152 | E3: 24 | F3: 1 | G3: 91.73 | H3: 0.05 | I3: 87.14
A4: 3 | B4: 2025-08-21 | C4: 8 | D4: 77 | E4: 84 | F4: 1 | G4: 26.78 | H4: 0.1 | I4: 24.1
A5: 4 | B5: 2024-07-23 | C5: 3 | D5: 123 | E5: 97 | F5: 5 | G5: 158.26 | H5: 0 | I5: 791.3
A6: 5 | B6: 2025-06-11 | C6: 8 | D6: 106 | E6: 30 | F6: 3 | G6: 19.4 | H6: 0 | I6: 58.2
A7: 6 | B7: 2023-07-06 | C7: 8 | D7: 64 | E7: 33 | F7: 1 | G7: 21.23 | H7: 0.05 | I7: 20.17
A8: 7 | B8: 2024-12-13 | C8: 7 | D8: 22 | E8: 16 | F8: 1 | G8: 62.77 | H8: 0 | I8: 62.77
A9: 8 | B9: 2024-11-13 | C9: 6 | D9: 89 | E9: 59 | F9: 1 | G9: 17.41 | H9: 0 | I9: 17.41
A10: 9 | B10: 2023-08-03 | C10: 3 | D10: 50 | E10: 30 | F10: 1 | G10: 19.4 | H10: 0 | I10: 19.4
A11: 10 | B11: 2024-11-06 | C11: 7 | D11: 207 | E11: 96 | F11: 1 | G11: 132.69 | H11: 0 | I11: 132.69
A12: 11 | B12: 2025-10-11 | C12: 5 | D12: 80 | E12: 48 | F12: 1 | G12: 146.85 | H12: 0 | I12: 146.85
A13: 12 | B13: 2025-03-31 | C13: 1 | D13: 45 | E13: 19 | F13: 1 | G13: 138.31 | H13: 0 | I13: 138.31
... A501: 500 | B501: 2024-11-02 | C501: 6 | D501: 128 | E501: 68 | F501: 1 | G501: 198.56 | H501: 0.05 | I501: 188.63

Sheet Customers
A1: customer_id | B1: name | C1: gender | D1: region | E1: signup_date | F1: loyalty_status
A2: 1 | B2: Customer 0001 | C2: Other | D2: North | E2: 2023-10-31 | F2: Silver
A3: 2 | B3: Customer 0002 | C3: Other | D3: South | E3: 2020-12-16 | F3: Bronze
A4: 3 | B4: Customer 0003 | C4: Female | D4: Central | E4: 2022-02-16 | F4: Bronze
A5: 4 | B5: Customer 0004 | C5: Male | D5: South | E5: 2021-10-26 | F5: Gold
A6: 5 | B6: Customer 0005 | C6: Female | D6: West | E6: 2024-07-06 | F6: Bronze
A7: 6 | B7: Customer 0006 | C7: Other | D7: East | E7: 2021-03-08 | F7: Bronze
A8: 7 | B8: Customer 0007 | C8: Female | D8: West | E8: 2022-10-19 | F8: Bronze
A9: 8 | B9: Customer 0008 | C9: Male | D9: Central | E9: 2020-10-12 | F9: Silver
A10: 9 | B10: Customer 0009 | C10: Other | D10: West | E10: 2024-03-09 | F10: Gold
A11: 10 | B11: Customer 0010 | C11: Female | D11: South | E11: 2022-03-28 | F11: Platinum
A12: 11 | B12: Customer 0011 | C12: Other | D12: West | E12: 2020-10-10 | F12: Bronze
A13: 12 | B13: Customer 0012 | C13: Male | D13: South | E13: 2020-04-06 | F13: Silver
... A221: 220 | B221: Customer 0220 | C221: Male | D221: South | E221: 2020-02-22 | F221: Platinum

Sheet Sales (2)
A1: sale_id | B1: date | C1: branch_id | D1: customer_id | E1: product_id | F1: quantity | G1: price | H1: discount | I1: total_amount
A2: 1 | B2: 44969 | C2: 5 | D2: 189 | E2: 97 | F2: 2 | G2: 158.26 | H2: 0 | I2: 316.52
A3: 2 | B3: 45009 | C3: 3 | D3: 152 | E3: 24 | F3: 1 | G3: 91.73 | H3: 0.05 | I3: 87.14
A4: 3 | B4: 45890 | C4: 8 | D4: 77 | E4: 84 | F4: 1 | G4: 26.78 | H4: 0.1 | I4: 24.1
A5: 4 | B5: 45496 | C5: 3 | D5: 123 | E5: 97 | F5: 5 | G5: 158.26 | H5: 0 | I5: 791.3
A6: 5 | B6: 45819 | C6: 8 | D6: 106 | E6: 30 | F6: 3 | G6: 19.4 | H6: 0 | I6: 58.2
A7: 6 | B7: 45113 | C7: 8 | D7: 64 | E7: 33 | F7: 1 | G7: 21.23 | H7: 0.05 | I7: 20.17
A8: 7 | B8: 45639 | C8: 7 | D8: 22 | E8: 16 | F8: 1 | G8: 62.77 | H8: 0 | I8: 62.77
A9: 8 | B9: 45609 | C9: 6 | D9: 89 | E9: 59 | F9: 1 | G9: 17.41 | H9: 0 | I9: 17.41
A10: 9 | B10: 45141 | C10: 3 | D10: 50 | E10: 30 | F10: 1 | G10: 19.4 | H10: 0 | I10: 19.4
A11: 10 | B11: 45602 | C11: 7 | D11: 207 | E11: 96 | F11: 1 | G11: 132.69 | H11: 0 | I11: 132.69
A12: 11 | B12: 45941 | C12: 5 | D12: 80 | E12: 48 | F12: 1 | G12: 146.85 | H12: 0 | I12: 146.85
A13: 12 | B13: 45747 | C13: 1 | D13: 45 | E13: 19 | F13: 1 | G13: 138.31 | H13: 0 | I13: 138.31
... A801: 800 | B801: 45964 | C801: 7 | D801: 218 | E801: 32 | F801: 2 | G801: 47.81 | H801: 0 | I801: 95.62

Sheet Products (2)
A1: product_id | B1: category | C1: product_name | D1: cost_price | E1: selling_price
A2: 1 | B2: Sports | C2: Product 001 | D2: 78.04 | E2: 90.53
A3: 2 | B3: Electronics | C3: Product 002 | D3: 190.39 | E3: 274.16
A4: 3 | B4: Electronics | C4: Product 003 | D4: 147.74 | E4: 190.58
A5: 4 | B5: Sports | C5: Product 004 | D5: 121.74 | E5: 168
A6: 5 | B6: Clothing | C6: Product 005 | D6: 35.42 | E6: 55.26
A7: 6 | B7: Home | C7: Product 006 | D7: 35.42 | E7: 44.63
A8: 7 | B8: Home | C8: Product 007 | D8: 16.33 | E8: 21.72
A9: 8 | B9: Home | C9: Product 008 | D9: 173.9 | E9: 259.11
A10: 9 | B10: Sports | C10: Product 009 | D10: 122.22 | E10: 152.78
A11: 10 | B11: Electronics | C11: Product 010 | D11: 143.07 | E11: 168.82
A12: 11 | B12: Sports | C12: Product 011 | D12: 9.01 | E12: 11.53
A13: 12 | B13: Sports | C13: Product 012 | D13: 194.13 | E13: 236.84
... A101: 100 | B101: Sports | C101: Product 100 | D101: 26.04 | E101: 39.06

Sheet Products
A1: product_id | B1: category | C1: product_name | D1: cost_price | E1: selling_price | F1: profit_per_sale
A2: 1 | B2: Sports | C2: Product 001 | D2: 78.04 | E2: 90.53 | F2: =Table8[[#This Row],[selling_price]]-Table8[[#This Row],[cost_price]] -> 12.49 | K2: product_id | L2: category
A3: 2 | B3: Electronics | C3: Product 002 | D3: 190.39 | E3: 274.16 | F3: =Table8[[#This Row],[selling_price]]-Table8[[#This Row],[cost_price]] -> 83.77 | K3: 1 | L3: Sports
A4: 3 | B4: Games | C4: Product 003 | D4: 147.74 | E4: 190.58 | F4: =Table8[[#This Row],[selling_price]]-Table8[[#This Row],[cost_price]] -> 42.84 | K4: 2 | L4: Electronics
A5: 4 | B5: Sports | C5: Product 004 | D5: 121.74 | E5: 168 | F5: =Table8[[#This Row],[selling_price]]-Table8[[#This Row],[cost_price]] -> 46.26 | K5: 3 | L5: Games
A6: 5 | B6: Clothing | C6: Product 005 | D6: 35.42 | E6: 55.26 | F6: =Table8[[#This Row],[selling_price]]-Table8[[#This Row],[cost_price]] -> 19.84 | K6: 4 | L6: Sports
A7: 6 | B7: Home | C7: Product 006 | D7: 35.42 | E7: 44.63 | F7: =Table8[[#This Row],[selling_price]]-Table8[[#This Row],[cost_price]] -> 9.21 | K7: 5 | L7: Clothing
A8: 7 | B8: Shoes | C8: Product 007 | D8: 16.33 | E8: 21.72 | F8: =Table8[[#This Row],[selling_price]]-Table8[[#This Row],[cost_price]] -> 5.39 | K8: 6 | L8: Home
A9: 8 | B9: Phones | C9: Product 008 | D9: 173.9 | E9: 259.11 | F9: =Table8[[#This Row],[selling_price]]-Table8[[#This Row],[cost_price]] -> 85.21 | K9: 7 | L9: Shoes
A10: 9 | B10: Jewelry | C10: Product 009 | D10: 122.22 | E10: 152.78 | F10: =Table8[[#This Row],[selling_price]]-Table8[[#This Row],[cost_price]] -> 30.56 | K10: 8 | L10: Phones
A11: 10 | B11: Women's Fashion | C11: Product 010 | D11: 143.07 | E11: 168.82 | F11: =Table8[[#This Row],[selling_price]]-Table8[[#This Row],[cost_price]] -> 25.75 | K11: 9 | L11: Jewelry
A12: 11 | B12: Sports | C12: Product 011 | D12: 9.01 | E12: 11.53 | F12: =Table8[[#This Row],[selling_price]]-Table8[[#This Row],[cost_price]] -> 2.52 | K12: 10 | L12: Women's Fashion
A13: 12 | B13: Sports | C13: Product 012 | D13: 194.13 | E13: 236.84 | F13: =Table8[[#This Row],[selling_price]]-Table8[[#This Row],[cost_price]] -> 42.71
A14: 23 | B14: Beauty | C14: Product 023 | D14: 61.97 | E14: 79.94 | F14: =Table8[[#This Row],[selling_price]]-Table8[[#This Row],[cost_price]] -> 17.97
A15: 24 | B15: Electronics | C15: Product 024 | D15: 76.44 | E15: 91.73 | F15: =Table8[[#This Row],[selling_price]]-Table8[[#This Row],[cost_price]] -> 15.29
A16: 25 | B16: Beauty | C16: Product 025 | D16: 93.93 | E16: 117.41 | F16: =Table8[[#This Row],[selling_price]]-Table8[[#This Row],[cost_price]] -> 23.48
A17: 26 | B17: Home | C17: Product 026 | D17: 158.11 | E17: 211.87 | F17: =Table8[[#This Row],[selling_price]]-Table8[[#This Row],[cost_price]] -> 53.76
A18: 27 | B18: Sports | C18: Product 027 | D18: 43.94 | E18: 66.79 | F18: =Table8[[#This Row],[selling_price]]-Table8[[#This Row],[cost_price]] -> 22.85
A19: 28 | B19: Sports | C19: Product 028 | D19: 105.28 | E19: 162.13 | F19: =Table8[[#This Row],[selling_price]]-Table8[[#This Row],[cost_price]] -> 56.85
A20: 29 | B20: Sports | C20: Product 029 | D20: 120.52 | E20: 138.6 | F20: =Table8[[#This Row],[selling_price]]-Table8[[#This Row],[cost_price]] -> 18.08
A21: 30 | B21: Beauty | C21: Product 030 | D21: 14.06 | E21: 19.4 | F21: =Table8[[#This Row],[selling_price]]-Table8[[#This Row],[cost_price]] -> 5.34
A22: 31 | B22: Toys | C22: Product 031 | D22: 123.47 | E22: 165.45 | F22: =Table8[[#This Row],[selling_price]]-Table8[[#This Row],[cost_price]] -> 41.98
A23: 32 | B23: Home | C23: Product 032 | D23: 38.25 | E23: 47.81 | F23: =Table8[[#This Row],[selling_price]]-Table8[[#This Row],[cost_price]] -> 9.56
A24: 33 | B24: Toys | C24: Product 033 | D24: 17.69 | E24: 21.23 | F24: =Table8[[#This Row],[selling_price]]-Table8[[#This Row],[cost_price]] -> 3.54
... A91: 100 | B91: Sports | C91: Product 100 | D91: 26.04 | E91: 39.06 | F91: =Table8[[#This Row],[selling_price]]-Table8[[#This Row],[cost_price]] -> 13.02

Sheet Sheet2
A3: Row Labels | B3: Sum of Sales.total_amount | D3: Row Labels | E3: Sum of Sales.total_amount | G3: Row Labels | H3: Sum of Sales.total_amount | J3: Row Labels | K3: Sum of Sales.total_amount | M3: Row Labels | N3: Sum of profit_per.sale | O3: Sum of Sales.total_amount | P3: Row Labels | Q3: Sum of profit_per.sale
A4: South | B4: 46055.022 | D4: Oct | E4: 18205.104 | G4: Customer004 | H4: 3395.054 | J4: Beauty | K4: 8660.1765 | M4: West | N4: 11918.316 | O4: 31558.984 | P4: 2023 | Q4: 20282.029 | S4: Row Labels | T4: Count of Sales.quantity | U4: Average of Products.cost_price | V4: Average of Products.selling_price | W4: Average of profit_per.sale
A5: North | B5: 44082.314 | D5: Aug | E5: 16683.512 | G5: Customer009 | H5: 3040.7075 | J5: Clothing | K5: 19290.312 | M5: South | N5: 18642.998 | O5: 46055.022 | P5: 2024 | Q5: 18176.67 | S5: Beauty | T5: 58 | U5: 78.655172 | V5: 104.7219 | W5: 43.773509
A6: East | B6: 35473.128 | D6: Jul | E6: 16488.863 | G6: Customer014 | H6: 2950.7555 | J6: Games | K6: 42012.251 | M6: North | N6: 14969.366 | O6: 44082.314 | P6: 2025 | Q6: 19468.853 | S6: Clothing | T6: 58 | U6: 206.56897 | V6: 258.79379 | W6: 92.252216
A7: West | B7: 31558.984 | D7: Sep | E7: 16194.354 | G7: Customer015 | H7: 3938.9735 | J7: Groceries | K7: 6453.5015 | M7: East | N7: 12396.872 | O7: 35473.128 | P7: Grand Total | Q7: 57927.552 | S7: Games | T7: 60 | U7: 538.93333 | V7: 697.06917 | W7: 328.41515
A8: Grand Total | B8: 157169.45 | D8: Nov | E8: 15678.493 | G8: Customer018 | H8: 3271.4425 | J8: Home Appliances | K8: 22697.026 | M8: Grand Total | N8: 57927.552 | O8: 157169.45 | S8: Groceries | T8: 49 | U8: 76.326531 | V8: 100.98714 | W8: 34.924867
D9: Grand Total | E9: 83250.326 | G9: Customer023 | H9: 3137.173 | J9: Jewelry | K9: 10945.069 | S9: Home Appliances | T9: 49 | U9: 350.61224 | V9: 448.84673 | W9: 204.98355
A10: Row Labels | B10: Sum of Sales.total_amount | G10: Customer030 | H10: 4288.14 | J10: Shoes | K10: 21512.949 | S10: Jewelry | T10: 68 | U10: 104.64706 | V10: 137.52735 | W10: 45.387228
A11: Games | B11: 42012.251 | D11: Row Labels | E11: Sum of profit_per.sale | G11: Customer032 | H11: 4727.739 | J11: Sports | K11: 14040.187 | M11: Row Labels | N11: Sum of profit_per.sale | P11: Row Labels | Q11: Count of Sales.quantity | S11: Shoes | T11: 51 | U11: 268.84314 | V11: 346.3702 | W11: 158.31787
A12: Home Appliances | B12: 22697.026 | D12: Beauty | E12: 2538.8635 | G12: Customer037 | H12: 3225.706 | J12: Toys | K12: 11326.558 | M12: January | N12: 6248.065 | P12: 2023 | Q12: 175 | S12: Sports | T12: 51 | U12: 178.7451 | V12: 231.19608 | W12: 77.941441
A13: Shoes | B13: 21512.949 | D13: Clothing | E13: 5350.6285 | G13: Customer060 | H13: 4110.5525 | J13: (blank) | K13: 231.42 | M13: 2023 | N13: 3872.2065 | P13: 2024 | Q13: 170 | S13: Toys | T13: 54 | U13: 118.51852 | V13: 157.64389 | W13: 62.764852
A14: Clothing | B14: 19290.312 | D14: Games | E14: 19704.909 | G14: Grand Total | H14: 36086.243 | J14: Grand Total | K14: 157169.45 | M14: 2024 | N14: 1038.434 | P14: 2025 | Q14: 154 | S14: (blank) | T14: 1 | U14: 203 | V14: 243.6 | W14: 52.78
A15: Sports | B15: 14040.187 | D15: Groceries | E15: 1711.3185 | M15: 2025 | N15: 1337.4245 | P15: Grand Total | Q15: 499 | S15: Grand Total | T15: 499 | U15: 213.11623 | V15: 275.37882 | W15: 116.08728
A16: Toys | B16: 11326.558 | D16: Home Appliances | E16: 10044.194 | G16: Row Labels | H16: Sum of Sales.quantity | J16: Row Labels | K16: Sum of profit_per.sale | M16: February | N16: 3195.815
A17: Jewelry | B17: 10945.069 | D17: Jewelry | E17: 3086.3315 | G17: Oct | H17: 78 | J17: Beauty | K17: 2538.8635 | M17: 2023 | N17: 951.153
A18: Beauty | B18: 8660.1765 | D18: Shoes | E18: 8074.2115 | G18: Nov | H18: 77 | J18: Clothing | K18: 5350.6285 | M18: 2024 | N18: 2069.512 | P18: Row Labels | Q18: Sum of profit_per.sale | R18: Sum of Sales.quantity
A19: Groceries | B19: 6453.5015 | D19: Sports | E19: 3975.0135 | G19: Jul | H19: 68 | J19: Games | K19: 19704.909 | M19: 2025 | N19: 175.15 | P19: January | Q19: 6248.065 | R19: 63
A20: (blank) | B20: 231.42 | D20: Toys | E20: 3389.302 | G20: Apr | H20: 65 | J20: Groceries | K20: 1711.3185 | M20: March | N20: 2329.4405 | P20: 2023 | Q20: 3872.2065 | R20: 39
A21: Grand Total | B21: 157169.45 | D21: (blank) | E21: 52.78 | G21: Aug | H21: 62 | J21: Home Appliances | K21: 10044.194 | M21: 2023 | N21: 194.0665 | P21: 2024 | Q21: 1038.434 | R21: 9
D22: Grand Total | E22: 57927.552 | G22: Sep | H22: 57 | J22: Jewelry | K22: 3086.3315 | M22: 2024 | N22: 1999.23 | P22: 2025 | Q22: 1337.4245 | R22: 15
A23: Row Labels | B23: Sum of Sales.total_amount | G23: Jun | H23: 55 | J23: Shoes | K23: 8074.2115 | M23: 2025 | N23: 136.144 | P23: February | Q23: 3195.815 | R23: 31
A24: Oct | B24: 18205.103 | G24: Mar | H24: 54 | J24: Sports | K24: 3975.0135 | M24: April | N24: 7305.864 | P24: 2023 | Q24: 951.153 | R24: 15
A25: Beauty | B25: 965.184 | D25: Row Labels | E25: Count of name | G25: May | H25: 52 | J25: Toys | K25: 3389.302 | M25: 2023 | N25: 1839.395 | P25: 2024 | Q25: 2069.512 | R25: 11
A26: Clothing | B26: 519.171 | D26: Bronze | E26: 221 | G26: Jan | H26: 44 | J26: (blank) | K26: 52.78 | M26: 2024 | N26: 2412.481 | P26: 2025 | Q26: 175.15 | R26: 5
A27: Games | B27: 8412.571 | D27: Gold | E27: 114 | G27: Feb | H27: 35 | J27: Grand Total | K27: 57927.552 | M27: 2025 | N27: 3053.988 | P27: March | Q27: 2329.4405 | R27: 36
A28: Groceries | B28: 1010.552 | D28: Platinum | E28: 31 | G28: Dec | H28: 25 | M28: May | N28: 4724.7435 | P28: 2023 | Q28: 194.0665 | R28: 3
A29: Home Appliances | B29: 2805.0285 | D29: Silver | E29: 133 | G29: Grand Total | H29: 672 | M29: 2023 | N29: 1143.9215 | P29: 2024 | Q29: 1999.23 | R29: 30
A30: Jewelry | B30: 849.271 | D30: Grand Total | E30: 499 | M30: 2024 | N30: 2484.7995 | P30: 2025 | Q30: 136.144 | R30: 3
A31: Shoes | B31: 911.1165 | M31: 2025 | N31: 1096.0225 | P31: April | Q31: 7305.864 | R31: 104
A32: Sports | B32: 1607.4665 | M32: June | N32: 7991.612 | P32: 2023 | Q32: 1839.395 | R32: 27
A33: Toys | B33: 1124.743 | D33: Sum of Products.cost_price | E33: Sum of Sales.total_amount | F33: Sum of profit_per.sale | G33: Row Labels | H33: Count of Frequency table | I33: Average of Sales.total_amount | M33: 2023 | N33: 2597.487 | P33: 2024 | Q33: 2412.481 | R33: 39
A34: Aug | B34: 16683.513 | D34: 106345 | E34: 157169.45 | F34: 57927.552 | G34: Bronze | H34: 221 | I34: 331.05115 | M34: 2024 | N34: 3039.423 | P34: 2025 | Q34: 3053.988 | R34: 38
A35: Beauty | B35: 165.96 | G35: Gold | H35: 114 | I35: 292.74519 | M35: 2025 | N35: 2354.702 | P35: May | Q35: 4724.7435 | R35: 69
A36: Clothing | B36: 2199.1805 | G36: Platinum | H36: 31 | I36: 272.86961 | M36: July | N36: 5757.491 | P36: 2023 | Q36: 1143.9215 | R36: 13
A37: Games | B37: 3603.822 | G37: Silver | H37: 133 | I37: 317.10703 | M37: 2023 | N37: 3189.959 | P37: 2024 | Q37: 2484.7995 | R37: 42
A38: Groceries | B38: 969.694 | G38: Grand Total | H38: 499 | I38: 314.96883 | M38: 2024 | N38: 2030.9495 | P38: 2025 | Q38: 1096.0225 | R38: 14
A39: Home Appliances | B39: 2781.16 | M39: 2025 | N39: 536.5825 | P39: June | Q39: 7991.612 | R39: 91
A40: Jewelry | B40: 1903.8445 | D40: Row Labels | E40: Sum of profit_per.sale | M40: August | N40: 1826.518 | P40: 2023 | Q40: 2597.487 | R40: 26
A41: Shoes | B41: 3309.8295 | D41: West | E41: 11918.316 | M41: 2023 | N41: 436.1755 | P41: 2024 | Q41: 3039.423 | R41: 43
A42: Sports | B42: 820.5585 | D42: South | E42: 18642.998 | M42: 2024 | N42: 102.9325 | P42: 2025 | Q42: 2354.702 | R42: 22
...

Sheet combined_tbl
A1: customer_id | B1: first_purchase | C1: tenure_months | D1: Frequency table | E1: name | F1: gender | G1: region | H1: signup_date | I1: day | J1: month | K1: year | L1: loyalty_status | M1: Products.product_id | N1: Products.category | O1: Products.product_name | P1: Products.cost_price | Q1: Products.selling_price | R1: Sales.sale_id | S1: sales_Month | T1: Sales.date | U1: Sales.branch_id | V1: Sales.customer_id | W1: Sales.product_id | X1: Sales.quantity | Y1: Sales.price | Z1: Sales.discount | AA1: Sales.total_amount | AB1: profit_per.sale | AF1: =CHOOSE(RANDBETWEEN(1,4),"West","East","North","South") -> North | AI1: ="Customer"&TEXT(ROW(A1),"000") -> Customer001 | AJ1: =DATE(2023,1,1)+RANDBETWEEN(0,1095) -> 45260
A2: 1 | B2: {=MIN(IF($E:$E=E2,$H:$H))} -> 45474 | C2: =DATEDIF(B2,MAX($H:$H),"m") -> 17 | D2: =COUNTIF(E:E,combined_tbl!$E2) -> 2 | E2: =IF(RAND()<=0.5, "Customer"&TEXT(RANDBETWEEN(1,30),"000"), IF(RAND()<=0.8, "Customer"&TEXT(RANDBETWEEN(31,80),"000"), "Customer"&TEXT(RANDBETWEEN(81,139),"000"))) -> Customer139 | F2: {=INDEX({"Male","Female"}, RANDBETWEEN(1,2))} -> Male | G2: =_xlfn.XLOOKUP(E2,AI$1:AI$139,AF$1:AF$139) -> West | H2: =_xlfn.XLOOKUP(E2,AI$1:AI$139,AJ$1:AJ$139) -> 45474 | I2: =DAY(H2) -> 1 | J2: =TEXT(H2,"mmmm") -> July | K2: =YEAR(H2) -> 2024 | L2: =IF(AND(D2>=10,C2>=24),"Platinum",IF(AND(D2>=7,C2>=18),"Gold",IF(AND(D2>=3,C2>=12),"Silver","Bronze"))) -> Bronze | M2: 2 | N2: Clothing | O2: Product 002 | P2: 301 | Q2: 394.31 | R2: 2 | S2: =TEXT(T2,"MMM") -> Mar | T2: 45009 | U2: 3 | V2: 152 | W2: 24 | X2: 1 | Y2: =combined_tbl!$Q2*(1-combined_tbl!$Z2) -> 374.5945 | Z2: =IF(combined_tbl!$Q2>=500,0.2, IF(combined_tbl!$Q2>=200,0.05, IF(combined_tbl!$X2>=2,0.05,0))) -> 0.05 | AA2: =combined_tbl!$Y2*combined_tbl!$X2 -> 374.5945 | AB2: =(combined_tbl!$Q2*(1+combined_tbl!$Z2)-combined_tbl!$P2)*combined_tbl!$X2 -> 113.0255 | AF2: =CHOOSE(RANDBETWEEN(1,4),"West","East","North","South") -> South | AI2: ="Customer"&TEXT(ROW(A2),"000") -> Customer002 | AJ2: =DATE(2023,1,1)+RANDBETWEEN(0,1095) -> 45582
A3: 2 | B3: {=MIN(IF($E:$E=E3,$H:$H))} -> 45085 | C3: =DATEDIF(B3,MAX($H:$H),"m") -> 29 | D3: =COUNTIF(E:E,combined_tbl!$E3) -> 10 | E3: =IF(RAND()<=0.5, "Customer"&TEXT(RANDBETWEEN(1,30),"000"), IF(RAND()<=0.8, "Customer"&TEXT(RANDBETWEEN(31,80),"000"), "Customer"&TEXT(RANDBETWEEN(81,139),"000"))) -> Customer007 | F3: {=INDEX({"Male","Female"}, RANDBETWEEN(1,2))} -> Male | G3: =_xlfn.XLOOKUP(E3,AI$1:AI$139,AF$2:AF$140) -> East | H3: =_xlfn.XLOOKUP(E3,AI$1:AI$139,AJ$1:AJ$139) -> 45085 | I3: =DAY(H3) -> 8 | J3: =TEXT(H3,"mmmm") -> June | K3: =YEAR(H3) -> 2023 | L3: =IF(AND(D3>=10,C3>=24),"Platinum",IF(AND(D3>=7,C3>=18),"Gold",IF(AND(D3>=3,C3>=12),"Silver","Bronze"))) -> Platinum | M3: 3 | N3: Clothing | O3: Product 003 | P3: 389 | Q3: 521.26 | R3: 3 | S3: =TEXT(T3,"MMM") -> Aug | T3: 45890 | U3: 8 | V3: 77 | W3: 84 | X3: 1 | Y3: =combined_tbl!$Q3*(1-combined_tbl!$Z3) -> 417.008 | Z3: =IF(combined_tbl!$Q3>=500,0.2, IF(combined_tbl!$Q3>=200,0.05, IF(combined_tbl!$X3>=2,0.05,0))) -> 0.2 | AA3: =combined_tbl!$Y3*combined_tbl!$X3 -> 417.008 | AB3: =(combined_tbl!$Q3*(1+combined_tbl!$Z3)-combined_tbl!$P3)*combined_tbl!$X3 -> 236.512 | AF3: =CHOOSE(RANDBETWEEN(1,4),"West","East","North","South") -> East | AI3: ="Customer"&TEXT(ROW(A3),"000") -> Customer003 | AJ3: =DATE(2023,1,1)+RANDBETWEEN(0,1095) -> 45495
A4: 3 | B4: {=MIN(IF($E:$E=E4,$H:$H))} -> 45014 | C4: =DATEDIF(B4,MAX($H:$H),"m") -> 32 | D4: =COUNTIF(E:E,combined_tbl!$E4) -> 10 | E4: =IF(RAND()<=0.5, "Customer"&TEXT(RANDBETWEEN(1,30),"000"), IF(RAND()<=0.8, "Customer"&TEXT(RANDBETWEEN(31,80),"000"), "Customer"&TEXT(RANDBETWEEN(81,139),"000"))) -> Customer022 | F4: {=INDEX({"Male","Female"}, RANDBETWEEN(1,2))} -> Female | G4: =_xlfn.XLOOKUP(E4,AI$1:AI$139,AF$2:AF$140) -> South | H4: =_xlfn.XLOOKUP(E4,AI$1:AI$139,AJ$1:AJ$139) -> 45014 | I4: =DAY(H4) -> 29 | J4: =TEXT(H4,"mmmm") -> March | K4: =YEAR(H4) -> 2023 | L4: =IF(AND(D4>=10,C4>=24),"Platinum",IF(AND(D4>=7,C4>=18),"Gold",IF(AND(D4>=3,C4>=12),"Silver","Bronze"))) -> Platinum | M4: 4 | N4: Shoes | O4: Product 004 | P4: 226 | Q4: 248.6 | R4: 4 | S4: =TEXT(T4,"MMM") -> Jul | T4: 45496 | U4: 3 | V4: 123 | W4: 97 | X4: 5 | Y4: =combined_tbl!$Q4*(1-combined_tbl!$Z4) -> 236.17 | Z4: =IF(combined_tbl!$Q4>=500,0.2, IF(combined_tbl!$Q4>=200,0.05, IF(combined_tbl!$X4>=2,0.05,0))) -> 0.05 | AA4: =combined_tbl!$Y4*combined_tbl!$X4 -> 1180.85 | AB4: =(combined_tbl!$Q4*(1+combined_tbl!$Z4)-combined_tbl!$P4)*combined_tbl!$X4 -> 175.15 | AF4: =CHOOSE(RANDBETWEEN(1,4),"West","East","North","South") -> East | AI4: ="Customer"&TEXT(ROW(A4),"000") -> Customer004 | AJ4: =DATE(2023,1,1)+RANDBETWEEN(0,1095) -> 45896
A5: 4 | B5: {=MIN(IF($E:$E=E5,$H:$H))} -> 45406 | C5: =DATEDIF(B5,MAX($H:$H),"m") -> 19 | D5: =COUNTIF(E:E,combined_tbl!$E5) -> 2 | E5: =IF(RAND()<=0.5, "Customer"&TEXT(RANDBETWEEN(1,30),"000"), IF(RAND()<=0.8, "Customer"&TEXT(RANDBETWEEN(31,80),"000"), "Customer"&TEXT(RANDBETWEEN(81,139),"000"))) -> Customer057 | F5: {=INDEX({"Male","Female"}, RANDBETWEEN(1,2))} -> Male | G5: =_xlfn.XLOOKUP(E5,AI$1:AI$139,AF$2:AF$140) -> West | H5: =_xlfn.XLOOKUP(E5,AI$1:AI$139,AJ$1:AJ$139) -> 45406 | I5: =DAY(H5) -> 24 | J5: =TEXT(H5,"mmmm") -> April | K5: =YEAR(H5) -> 2024 | L5: =IF(AND(D5>=10,C5>=24),"Platinum",IF(AND(D5>=7,C5>=18),"Gold",IF(AND(D5>=3,C5>=12),"Silver","Bronze"))) -> Bronze | M5: 5 | N5: Toys | O5: Product 005 | P5: 211 | Q5: 246.87 | R5: 5 | S5: =TEXT(T5,"MMM") -> Jun | T5: 45819 | U5: 8 | V5: 106 | W5: 30 | X5: 3 | Y5: =combined_tbl!$Q5*(1-combined_tbl!$Z5) -> 234.5265 | Z5: =IF(combined_tbl!$Q5>=500,0.2, IF(combined_tbl!$Q5>=200,0.05, IF(combined_tbl!$X5>=2,0.05,0))) -> 0.05 | AA5: =combined_tbl!$Y5*combined_tbl!$X5 -> 703.5795 | AB5: =(combined_tbl!$Q5*(1+combined_tbl!$Z5)-combined_tbl!$P5)*combined_tbl!$X5 -> 144.6405 | AF5: =CHOOSE(RANDBETWEEN(1,4),"West","East","North","South") -> West | AI5: ="Customer"&TEXT(ROW(A5),"000") -> Customer005 | AJ5: =DATE(2023,1,1)+RANDBETWEEN(0,1095) -> 45750
A6: 5 | B6: {=MIN(IF($E:$E=E6,$H:$H))} -> 45111 | C6: =DATEDIF(B6,MAX($H:$H),"m") -> 29 | D6: =COUNTIF(E:E,combined_tbl!$E6) -> 5 | E6: =IF(RAND()<=0.5, "Customer"&TEXT(RANDBETWEEN(1,30),"000"), IF(RAND()<=0.8, "Customer"&TEXT(RANDBETWEEN(31,80),"000"), "Customer"&TEXT(RANDBETWEEN(81,139),"000"))) -> Customer062 | F6: {=INDEX({"Male","Female"}, RANDBETWEEN(1,2))} -> Male | G6: =_xlfn.XLOOKUP(E6,AI$1:AI$139,AF$2:AF$140) -> South | H6: =_xlfn.XLOOKUP(E6,AI$1:AI$139,AJ$1:AJ$139) -> 45111 | I6: =DAY(H6) -> 4 | J6: =TEXT(H6,"mmmm") -> July | K6: =YEAR(H6) -> 2023 | L6: =IF(AND(D6>=10,C6>=24),"Platinum",IF(AND(D6>=7,C6>=18),"Gold",IF(AND(D6>=3,C6>=12),"Silver","Bronze"))) -> Silver | M6: 6 | N6: Shoes | O6: Product 006 | P6: 86 | Q6: 99.76 | R6: 6 | S6: =TEXT(T6,"MMM") -> Jul | T6: 45113 | U6: 8 | V6: 64 | W6: 33 | X6: 1 | Y6: =combined_tbl!$Q6*(1-combined_tbl!$Z6) -> 99.76 | Z6: =IF(combined_tbl!$Q6>=500,0.2, IF(combined_tbl!$Q6>=200,0.05, IF(combined_tbl!$X6>=2,0.05,0))) -> 0 | AA6: =combined_tbl!$Y6*combined_tbl!$X6 -> 99.76 | AB6: =(combined_tbl!$Q6*(1+combined_tbl!$Z6)-combined_tbl!$P6)*combined_tbl!$X6 -> 13.76 | AF6: =CHOOSE(RANDBETWEEN(1,4),"West","East","North","South") -> East | AI6: ="Customer"&TEXT(ROW(A6),"000") -> Customer006 | AJ6: =DATE(2023,1,1)+RANDBETWEEN(0,1095) -> 45787
A7: 6 | B7: {=MIN(IF($E:$E=E7,$H:$H))} -> 45094 | C7: =DATEDIF(B7,MAX($H:$H),"m") -> 29 | D7: =COUNTIF(E:E,combined_tbl!$E7) -> 9 | E7: =IF(RAND()<=0.5, "Customer"&TEXT(RANDBETWEEN(1,30),"000"), IF(RAND()<=0.8, "Customer"&TEXT(RANDBETWEEN(31,80),"000"), "Customer"&TEXT(RANDBETWEEN(81,139),"000"))) -> Customer069 | F7: {=INDEX({"Male","Female"}, RANDBETWEEN(1,2))} -> Female | G7: =_xlfn.XLOOKUP(E7,AI$1:AI$139,AF$2:AF$140) -> North | H7: =_xlfn.XLOOKUP(E7,AI$1:AI$139,AJ$1:AJ$139) -> 45094 | I7: =DAY(H7) -> 17 | J7: =TEXT(H7,"mmmm") -> June | K7: =YEAR(H7) -> 2023 | L7: =IF(AND(D7>=10,C7>=24),"Platinum",IF(AND(D7>=7,C7>=18),"Gold",IF(AND(D7>=3,C7>=12),"Silver","Bronze"))) -> Gold | M7: 7 | N7: Games | O7: Product 007 | P7: 867 | Q7: 1283.16 | R7: 7 | S7: =TEXT(T7,"MMM") -> Dec | T7: 45639 | U7: 7 | V7: 22 | W7: 16 | X7: 1 | Y7: =combined_tbl!$Q7*(1-combined_tbl!$Z7) -> 1026.528 | Z7: =IF(combined_tbl!$Q7>=500,0.2, IF(combined_tbl!$Q7>=200,0.05, IF(combined_tbl!$X7>=2,0.05,0))) -> 0.2 | AA7: =combined_tbl!$Y7*combined_tbl!$X7 -> 1026.528 | AB7: =(combined_tbl!$Q7*(1+combined_tbl!$Z7)-combined_tbl!$P7)*combined_tbl!$X7 -> 672.792 | AF7: =CHOOSE(RANDBETWEEN(1,4),"West","East","North","South") -> North | AI7: ="Customer"&TEXT(ROW(A7),"000") -> Customer007 | AJ7: =DATE(2023,1,1)+RANDBETWEEN(0,1095) -> 45085
A8: 7 | B8: {=MIN(IF($E:$E=E8,$H:$H))} -> 45587 | C8: =DATEDIF(B8,MAX($H:$H),"m") -> 13 | D8: =COUNTIF(E:E,combined_tbl!$E8) -> 2 | E8: =IF(RAND()<=0.5, "Customer"&TEXT(RANDBETWEEN(1,30),"000"), IF(RAND()<=0.8, "Customer"&TEXT(RANDBETWEEN(31,80),"000"), "Customer"&TEXT(RANDBETWEEN(81,139),"000"))) -> Customer120 | F8: {=INDEX({"Male","Female"}, RANDBETWEEN(1,2))} -> Male | G8: =_xlfn.XLOOKUP(E8,AI$1:AI$139,AF$2:AF$140) -> North | H8: =_xlfn.XLOOKUP(E8,AI$1:AI$139,AJ$1:AJ$139) -> 45587 | I8: =DAY(H8) -> 22 | J8: =TEXT(H8,"mmmm") -> October | K8: =YEAR(H8) -> 2024 | L8: =IF(AND(D8>=10,C8>=24),"Platinum",IF(AND(D8>=7,C8>=18),"Gold",IF(AND(D8>=3,C8>=12),"Silver","Bronze"))) -> Bronze | M8: 8 | N8: Clothing | O8: Product 008 | P8: 56 | Q8: 66.08 | R8: 8 | S8: =TEXT(T8,"MMM") -> Nov | T8: 45609 | U8: 6 | V8: 89 | W8: 59 | X8: 1 | Y8: =combined_tbl!$Q8*(1-combined_tbl!$Z8) -> 66.08 | Z8: =IF(combined_tbl!$Q8>=500,0.2, IF(combined_tbl!$Q8>=200,0.05, IF(combined_tbl!$X8>=2,0.05,0))) -> 0 | AA8: =combined_tbl!$Y8*combined_tbl!$X8 -> 66.08 | AB8: =(combined_tbl!$Q8*(1+combined_tbl!$Z8)-combined_tbl!$P8)*combined_tbl!$X8 -> 10.08 | AF8: =CHOOSE(RANDBETWEEN(1,4),"West","East","North","South") -> East | AI8: ="Customer"&TEXT(ROW(A8),"000") -> Customer008 | AJ8: =DATE(2023,1,1)+RANDBETWEEN(0,1095) -> 45115
A9: 8 | B9: {=MIN(IF($E:$E=E9,$H:$H))} -> 45743 | C9: =DATEDIF(B9,MAX($H:$H),"m") -> 8 | D9: =COUNTIF(E:E,combined_tbl!$E9) -> 5 | E9: =IF(RAND()<=0.5, "Customer"&TEXT(RANDBETWEEN(1,30),"000"), IF(RAND()<=0.8, "Customer"&TEXT(RANDBETWEEN(31,80),"000"), "Customer"&TEXT(RANDBETWEEN(81,139),"000"))) -> Customer031 | F9: {=INDEX({"Male","Female"}, RANDBETWEEN(1,2))} -> Male | G9: =_xlfn.XLOOKUP(E9,AI$1:AI$139,AF$2:AF$140) -> South | H9: =_xlfn.XLOOKUP(E9,AI$1:AI$139,AJ$1:AJ$139) -> 45743 | I9: =DAY(H9) -> 27 | J9: =TEXT(H9,"mmmm") -> March | K9: =YEAR(H9) -> 2025 | L9: =IF(AND(D9>=10,C9>=24),"Platinum",IF(AND(D9>=7,C9>=18),"Gold",IF(AND(D9>=3,C9>=12),"Silver","Bronze"))) -> Bronze | M9: 9 | N9: Jewelry | O9: Product 009 | P9: 167 | Q9: 240.48 | R9: 9 | S9: =TEXT(T9,"MMM") -> Aug | T9: 45141 | U9: 3 | V9: 50 | W9: 30 | X9: 1 | Y9: =combined_tbl!$Q9*(1-combined_tbl!$Z9) -> 228.456 | Z9: =IF(combined_tbl!$Q9>=500,0.2, IF(combined_tbl!$Q9>=200,0.05, IF(combined_tbl!$X9>=2,0.05,0))) -> 0.05 | AA9: =combined_tbl!$Y9*combined_tbl!$X9 -> 228.456 | AB9: =(combined_tbl!$Q9*(1+combined_tbl!$Z9)-combined_tbl!$P9)*combined_tbl!$X9 -> 85.504 | AF9: =CHOOSE(RANDBETWEEN(1,4),"West","East","North","South") -> West | AI9: ="Customer"&TEXT(ROW(A9),"000") -> Customer009 | AJ9: =DATE(2023,1,1)+RANDBETWEEN(0,1095) -> 45761
A10: 9 | B10: {=MIN(IF($E:$E=E10,$H:$H))} -> 45346 | C10: =DATEDIF(B10,MAX($H:$H),"m") -> 21 | D10: =COUNTIF(E:E,combined_tbl!$E10) -> 12 | E10: =IF(RAND()<=0.5, "Customer"&TEXT(RANDBETWEEN(1,30),"000"), IF(RAND()<=0.8, "Customer"&TEXT(RANDBETWEEN(31,80),"000"), "Customer"&TEXT(RANDBETWEEN(81,139),"000"))) -> Customer011 | F10: {=INDEX({"Male","Female"}, RANDBETWEEN(1,2))} -> Male | G10: =_xlfn.XLOOKUP(E10,AI$1:AI$139,AF$2:AF$140) -> East | H10: =_xlfn.XLOOKUP(E10,AI$1:AI$139,AJ$1:AJ$139) -> 45346 | I10: =DAY(H10) -> 24 | J10: =TEXT(H10,"mmmm") -> February | K10: =YEAR(H10) -> 2024 | L10: =IF(AND(D10>=10,C10>=24),"Platinum",IF(AND(D10>=7,C10>=18),"Gold",IF(AND(D10>=3,C10>=12),"Silver","Bronze"))) -> Gold | M10: 10 | N10: Groceries | O10: Product 010 | P10: 83 | Q10: 97.94 | R10: 10 | S10: =TEXT(T10,"MMM") -> Nov | T10: 45602 | U10: 7 | V10: 207 | W10: 96 | X10: 1 | Y10: =combined_tbl!$Q10*(1-combined_tbl!$Z10) -> 97.94 | Z10: =IF(combined_tbl!$Q10>=500,0.2, IF(combined_tbl!$Q10>=200,0.05, IF(combined_tbl!$X10>=2,0.05,0))) -> 0 | AA10: =combined_tbl!$Y10*combined_tbl!$X10 -> 97.94 | AB10: =(combined_tbl!$Q10*(1+combined_tbl!$Z10)-combined_tbl!$P10)*combined_tbl!$X10 -> 14.94 | AF10: =CHOOSE(RANDBETWEEN(1,4),"West","East","North","South") -> East | AI10: ="Customer"&TEXT(ROW(A10),"000") -> Customer010 | AJ10: =DATE(2023,1,1)+RANDBETWEEN(0,1095) -> 45297
A11: 10 | B11: {=MIN(IF($E:$E=E11,$H:$H))} -> 45115 | C11: =DATEDIF(B11,MAX($H:$H),"m") -> 28 | D11: =COUNTIF(E:E,combined_tbl!$E11) -> 8 | E11: =IF(RAND()<=0.5, "Customer"&TEXT(RANDBETWEEN(1,30),"000"), IF(RAND()<=0.8, "Customer"&TEXT(RANDBETWEEN(31,80),"000"), "Customer"&TEXT(RANDBETWEEN(81,139),"000"))) -> Customer008 | F11: {=INDEX({"Male","Female"}, RANDBETWEEN(1,2))} -> Male | G11: =_xlfn.XLOOKUP(E11,AI$1:AI$139,AF$2:AF$140) -> West | H11: =_xlfn.XLOOKUP(E11,AI$1:AI$139,AJ$1:AJ$139) -> 45115 | I11: =DAY(H11) -> 8 | J11: =TEXT(H11,"mmmm") -> July | K11: =YEAR(H11) -> 2023 | L11: =IF(AND(D11>=10,C11>=24),"Platinum",IF(AND(D11>=7,C11>=18),"Gold",IF(AND(D11>=3,C11>=12),"Silver","Bronze"))) -> Gold | M11: 11 | N11: Sports | O11: Product 011 | P11: 145 | Q11: 210.25 | R11: 11 | S11: =TEXT(T11,"MMM") -> Oct | T11: 45941 | U11: 5 | V11: 80 | W11: 48 | X11: 1 | Y11: =combined_tbl!$Q11*(1-combined_tbl!$Z11) -> 199.7375 | Z11: =IF(combined_tbl!$Q11>=500,0.2, IF(combined_tbl!$Q11>=200,0.05, IF(combined_tbl!$X11>=2,0.05,0))) -> 0.05 | AA11: =combined_tbl!$Y11*combined_tbl!$X11 -> 199.7375 | AB11: =(combined_tbl!$Q11*(1+combined_tbl!$Z11)-combined_tbl!$P11)*combined_tbl!$X11 -> 75.7625 | AF11: =CHOOSE(RANDBETWEEN(1,4),"West","East","North","South") -> East | AI11: ="Customer"&TEXT(ROW(A11),"000") -> Customer011 | AJ11: =DATE(2023,1,1)+RANDBETWEEN(0,1095) -> 45346
A12: 11 | B12: {=MIN(IF($E:$E=E12,$H:$H))} -> 45631 | C12: =DATEDIF(B12,MAX($H:$H),"m") -> 11 | D12: =COUNTIF(E:E,combined_tbl!$E12) -> 6 | E12: =IF(RAND()<=0.5, "Customer"&TEXT(RANDBETWEEN(1,30),"000"), IF(RAND()<=0.8, "Customer"&TEXT(RANDBETWEEN(31,80),"000"), "Customer"&TEXT(RANDBETWEEN(81,139),"000"))) -> Customer017 | F12: {=INDEX({"Male","Female"}, RANDBETWEEN(1,2))} -> Male | G12: =_xlfn.XLOOKUP(E12,AI$1:AI$139,AF$2:AF$140) -> West | H12: =_xlfn.XLOOKUP(E12,AI$1:AI$139,AJ$1:AJ$139) -> 45631 | I12: =DAY(H12) -> 5 | J12: =TEXT(H12,"mmmm") -> December | K12: =YEAR(H12) -> 2024 | L12: =IF(AND(D12>=10,C12>=24),"Platinum",IF(AND(D12>=7,C12>=18),"Gold",IF(AND(D12>=3,C12>=12),"Silver","Bronze"))) -> Bronze | M12: 12 | N12: Shoes | O12: Product 012 | P12: 248 | Q12: 342.24 | R12: 12 | S12: =TEXT(T12,"MMM") -> Mar | T12: 45747 | U12: 1 | V12: 45 | W12: 19 | X12: 1 | Y12: =combined_tbl!$Q12*(1-combined_tbl!$Z12) -> 325.128 | Z12: =IF(combined_tbl!$Q12>=500,0.2, IF(combined_tbl!$Q12>=200,0.05, IF(combined_tbl!$X12>=2,0.05,0))) -> 0.05 | AA12: =combined_tbl!$Y12*combined_tbl!$X12 -> 325.128 | AB12: =(combined_tbl!$Q12*(1+combined_tbl!$Z12)-combined_tbl!$P12)*combined_tbl!$X12 -> 111.352 | AF12: =CHOOSE(RANDBETWEEN(1,4),"West","East","North","South") -> East | AI12: ="Customer"&TEXT(ROW(A12),"000") -> Customer012 | AJ12: =DATE(2023,1,1)+RANDBETWEEN(0,1095) -> 45268
A13: 12 | B13: {=MIN(IF($E:$E=E13,$H:$H))} -> 44960 | C13: =DATEDIF(B13,MAX($H:$H),"m") -> 34 | D13: =COUNTIF(E:E,combined_tbl!$E13) -> 6 | E13: =IF(RAND()<=0.5, "Customer"&TEXT(RANDBETWEEN(1,30),"000"), IF(RAND()<=0.8, "Customer"&TEXT(RANDBETWEEN(31,80),"000"), "Customer"&TEXT(RANDBETWEEN(81,139),"000"))) -> Customer042 | F13: {=INDEX({"Male","Female"}, RANDBETWEEN(1,2))} -> Male | G13: =_xlfn.XLOOKUP(E13,AI$1:AI$139,AF$2:AF$140) -> East | H13: =_xlfn.XLOOKUP(E13,AI$1:AI$139,AJ$1:AJ$139) -> 44960 | I13: =DAY(H13) -> 3 | J13: =TEXT(H13,"mmmm") -> February | K13: =YEAR(H13) -> 2023 | L13: =IF(AND(D13>=10,C13>=24),"Platinum",IF(AND(D13>=7,C13>=18),"Gold",IF(AND(D13>=3,C13>=12),"Silver","Bronze"))) -> Silver | M13: 13 | N13: Games | O13: Product 013 | P13: 637 | Q13: 777.14 | R13: 13 | S13: =TEXT(T13,"MMM") -> Jul | T13: 45858 | U13: 2 | V13: 177 | W13: 26 | X13: 2 | Y13: =combined_tbl!$Q13*(1-combined_tbl!$Z13) -> 621.712 | Z13: =IF(combined_tbl!$Q13>=500,0.2, IF(combined_tbl!$Q13>=200,0.05, IF(combined_tbl!$X13>=2,0.05,0))) -> 0.2 | AA13: =combined_tbl!$Y13*combined_tbl!$X13 -> 1243.424 | AB13: =(combined_tbl!$Q13*(1+combined_tbl!$Z13)-combined_tbl!$P13)*combined_tbl!$X13 -> 591.136 | AF13: =CHOOSE(RANDBETWEEN(1,4),"West","East","North","South") -> East | AI13: ="Customer"&TEXT(ROW(A13),"000") -> Customer013 | AJ13: =DATE(2023,1,1)+RANDBETWEEN(0,1095) -> 45995
A14: 13 | B14: {=MIN(IF($E:$E=E14,$H:$H))} -> 45495 | C14: =DATEDIF(B14,MAX($H:$H),"m") -> 16 | D14: =COUNTIF(E:E,combined_tbl!$E14) -> 8 | E14: =IF(RAND()<=0.5, "Customer"&TEXT(RANDBETWEEN(1,30),"000"), IF(RAND()<=0.8, "Customer"&TEXT(RANDBETWEEN(31,80),"000"), "Customer"&TEXT(RANDBETWEEN(81,139),"000"))) -> Customer003 | F14: {=INDEX({"Male","Female"}, RANDBETWEEN(1,2))} -> Male | G14: =_xlfn.XLOOKUP(E14,AI$1:AI$139,AF$2:AF$140) -> East | H14: =_xlfn.XLOOKUP(E14,AI$1:AI$139,AJ$1:AJ$139) -> 45495 | I14: =DAY(H14) -> 22 | J14: =TEXT(H14,"mmmm") -> July | K14: =YEAR(H14) -> 2024 | L14: =IF(AND(D14>=10,C14>=24),"Platinum",IF(AND(D14>=7,C14>=18),"Gold",IF(AND(D14>=3,C14>=12),"Silver","Bronze"))) -> Silver | M14: 14 | N14: Beauty | O14: Product 014 | P14: 29 | Q14: 37.7 | R14: 14 | S14: =TEXT(T14,"MMM") -> Oct | T14: 45571 | U14: 5 | V14: 172 | W14: 66 | X14: 2 | Y14: =combined_tbl!$Q14*(1-combined_tbl!$Z14) -> 35.815 | Z14: =IF(combined_tbl!$Q14>=500,0.2, IF(combined_tbl!$Q14>=200,0.05, IF(combined_tbl!$X14>=2,0.05,0))) -> 0.05 | AA14: =combined_tbl!$Y14*combined_tbl!$X14 -> 71.63 | AB14: =(combined_tbl!$Q14*(1+combined_tbl!$Z14)-combined_tbl!$P14)*combined_tbl!$X14 -> 21.17 | AF14: =CHOOSE(RANDBETWEEN(1,4),"West","East","North","South") -> North | AI14: ="Customer"&TEXT(ROW(A14),"000") -> Customer014 | AJ14: =DATE(2023,1,1)+RANDBETWEEN(0,1095) -> 45103
... A53: 52 | B53: {=MIN(IF($E:$E=E53,$H:$H))} -> 45637 | C53: =DATEDIF(B53,MAX($H:$H),"m") -> 11 | D53: =COUNTIF(E:E,combined_tbl!$E53) -> 4 | E53: =IF(RAND()<=0.5, "Customer"&TEXT(RANDBETWEEN(1,30),"000"), IF(RAND()<=0.8, "Customer"&TEXT(RANDBETWEEN(31,80),"000"), "Customer"&TEXT(RANDBETWEEN(81,139),"000"))) -> Customer059 | F53: {=INDEX({"Male","Female"}, RANDBETWEEN(1,2))} -> Male | G53: =_xlfn.XLOOKUP(E53,AI$1:AI$139,AF$2:AF$140) -> East | H53: =_xlfn.XLOOKUP(E53,AI$1:AI$139,AJ$1:AJ$139) -> 45637 | I53: =DAY(H53) -> 11 | J53: =TEXT(H53,"mmmm") -> December | K53: =YEAR(H53) -> 2024 | L53: =IF(AND(D53>=10,C53>=24),"Platinum",IF(AND(D53>=7,C53>=18),"Gold",IF(AND(D53>=3,C53>=12),"Silver","Bronze"))) -> Bronze | M53: 53 | N53: Home Appliances | O53: Product 053 | P53: 176 | Q53: 235.84 | R53: 53 | S53: =TEXT(T53,"MMM") -> Oct | T53: 45955 | U53: 6 | V53: 195 | W53: 4 | X53: 1 | Y53: =combined_tbl!$Q53*(1-combined_tbl!$Z53) -> 224.048 | Z53: =IF(combined_tbl!$Q53>=500,0.2, IF(combined_tbl!$Q53>=200,0.05, IF(combined_tbl!$X53>=2,0.05,0))) -> 0.05 | AA53: =combined_tbl!$Y53*combined_tbl!$X53 -> 224.048 | AB53: =(combined_tbl!$Q53*(1+combined_tbl!$Z53)-combined_tbl!$P53)*combined_tbl!$X53 -> 71.632 | AF53: =CHOOSE(RANDBETWEEN(1,4),"West","East","North","South") -> South | AI53: ="Customer"&TEXT(ROW(A53),"000") -> Customer053 | AJ53: =DATE(2023,1,1)+RANDBETWEEN(0,1095) -> 45356
A54: 53 | B54: {=MIN(IF($E:$E=E54,$H:$H))} -> 45991 | C54: =DATEDIF(B54,MAX($H:$H),"m") -> 0 | D54: =COUNTIF(E:E,combined_tbl!$E54) -> 9 | E54: =IF(RAND()<=0.5, "Customer"&TEXT(RANDBETWEEN(1,30),"000"), IF(RAND()<=0.8, "Customer"&TEXT(RANDBETWEEN(31,80),"000"), "Customer"&TEXT(RANDBETWEEN(81,139),"000"))) -> Customer029 | F54: {=INDEX({"Male","Female"}, RANDBETWEEN(1,2))} -> Male | G54: =_xlfn.XLOOKUP(E54,AI$1:AI$139,AF$1:AF$139) -> East | H54: =_xlfn.XLOOKUP(E54,AI$1:AI$139,AJ$1:AJ$139) -> 45991 | I54: =DAY(H54) -> 30 | J54: =TEXT(H54,"mmmm") -> November | K54: =YEAR(H54) -> 2025 | L54: =IF(AND(D54>=10,C54>=24),"Platinum",IF(AND(D54>=7,C54>=18),"Gold",IF(AND(D54>=3,C54>=12),"Silver","Bronze"))) -> Bronze | M54: 54 | N54: Shoes | O54: Product 054 | P54: 71 | Q54: 95.85 | R54: 54 | S54: =TEXT(T54,"MMM") -> Jul | T54: 45132 | U54: 8 | V54: 17 | W54: 50 | X54: 1 | Y54: =combined_tbl!$Q54*(1-combined_tbl!$Z54) -> 95.85 | Z54: =IF(combined_tbl!$Q54>=500,0.2, IF(combined_tbl!$Q54>=200,0.05, IF(combined_tbl!$X54>=2,0.05,0))) -> 0 | AA54: =combined_tbl!$Y54*combined_tbl!$X54 -> 95.85 | AB54: =(combined_tbl!$Q54*(1+combined_tbl!$Z54)-combined_tbl!$P54)*combined_tbl!$X54 -> 24.85 | AF54: =CHOOSE(RANDBETWEEN(1,4),"West","East","North","South") -> North | AI54: ="Customer"&TEXT(ROW(A54),"000") -> Customer054 | AJ54: =DATE(2023,1,1)+RANDBETWEEN(0,1095) -> 44938
A55: 54 | B55: {=MIN(IF($E:$E=E55,$H:$H))} -> 45625 | C55: =DATEDIF(B55,MAX($H:$H),"m") -> 12 | D55: =COUNTIF(E:E,combined_tbl!$E55) -> 7 | E55: =IF(RAND()<=0.5, "Customer"&TEXT(RANDBETWEEN(1,30),"000"), IF(RAND()<=0.8, "Customer"&TEXT(RANDBETWEEN(31,80),"000"), "Customer"&TEXT(RANDBETWEEN(81,139),"000"))) -> Customer038 | F55: {=INDEX({"Male","Female"}, RANDBETWEEN(1,2))} -> Female | G55: =_xlfn.XLOOKUP(E55,AI$1:AI$139,AF$2:AF$140) -> West | H55: =_xlfn.XLOOKUP(E55,AI$1:AI$139,AJ$1:AJ$139) -> 45625 | I55: =DAY(H55) -> 29 | J55: =TEXT(H55,"mmmm") -> November | K55: =YEAR(H55) -> 2024 | L55: =IF(AND(D55>=10,C55>=24),"Platinum",IF(AND(D55>=7,C55>=18),"Gold",IF(AND(D55>=3,C55>=12),"Silver","Bronze"))) -> Silver | M55: 55 | N55: Clothing | O55: Product 055 | P55: 214 | Q55: 291.04 | R55: 55 | S55: =TEXT(T55,"MMM") -> Jul | T55: 45131 | U55: 8 | V55: 200 | W55: 64 | X55: 1 | Y55: =combined_tbl!$Q55*(1-combined_tbl!$Z55) -> 276.488 | Z55: =IF(combined_tbl!$Q55>=500,0.2, IF(combined_tbl!$Q55>=200,0.05, IF(combined_tbl!$X55>=2,0.05,0))) -> 0.05 | AA55: =combined_tbl!$Y55*combined_tbl!$X55 -> 276.488 | AB55: =(combined_tbl!$Q55*(1+combined_tbl!$Z55)-combined_tbl!$P55)*combined_tbl!$X55 -> 91.592 | AF55: =CHOOSE(RANDBETWEEN(1,4),"West","East","North","South") -> West | AI55: ="Customer"&TEXT(ROW(A55),"000") -> Customer055 | AJ55: =DATE(2023,1,1)+RANDBETWEEN(0,1095) -> 45922
A56: 55 | B56: {=MIN(IF($E:$E=E56,$H:$H))} -> 45237 | C56: =DATEDIF(B56,MAX($H:$H),"m") -> 24 | D56: =COUNTIF(E:E,combined_tbl!$E56) -> 1 | E56: =IF(RAND()<=0.5, "Customer"&TEXT(RANDBETWEEN(1,30),"000"), IF(RAND()<=0.8, "Customer"&TEXT(RANDBETWEEN(31,80),"000"), "Customer"&TEXT(RANDBETWEEN(81,139),"000"))) -> Customer083 | F56: {=INDEX({"Male","Female"}, RANDBETWEEN(1,2))} -> Female | G56: =_xlfn.XLOOKUP(E56,AI$1:AI$139,AF$2:AF$140) -> West | H56: =_xlfn.XLOOKUP(E56,AI$1:AI$139,AJ$1:AJ$139) -> 45237 | I56: =DAY(H56) -> 7 | J56: =TEXT(H56,"mmmm") -> November | K56: =YEAR(H56) -> 2023 | L56: =IF(AND(D56>=10,C56>=24),"Platinum",IF(AND(D56>=7,C56>=18),"Gold",IF(AND(D56>=3,C56>=12),"Silver","Bronze"))) -> Bronze | M56: 56 | N56: Groceries | O56: Product 056 | P56: 118 | Q56: 164.02 | R56: 56 | S56: =TEXT(T56,"MMM") -> Feb | T56: 44958 | U56: 3 | V56: 139 | W56: 44 | X56: 1 | Y56: =combined_tbl!$Q56*(1-combined_tbl!$Z56) -> 164.02 | Z56: =IF(combined_tbl!$Q56>=500,0.2, IF(combined_tbl!$Q56>=200,0.05, IF(combined_tbl!$X56>=2,0.05,0))) -> 0 | AA56: =combined_tbl!$Y56*combined_tbl!$X56 -> 164.02 | AB56: =(combined_tbl!$Q56*(1+combined_tbl!$Z56)-combined_tbl!$P56)*combined_tbl!$X56 -> 46.02 | AF56: =CHOOSE(RANDBETWEEN(1,4),"West","East","North","South") -> North | AI56: ="Customer"&TEXT(ROW(A56),"000") -> Customer056 | AJ56: =DATE(2023,1,1)+RANDBETWEEN(0,1095) -> 45047
A57: 56 | B57: {=MIN(IF($E:$E=E57,$H:$H))} -> 45182 | C57: =DATEDIF(B57,MAX($H:$H),"m") -> 26 | D57: =COUNTIF(E:E,combined_tbl!$E57) -> 13 | E57: =IF(RAND()<=0.5, "Customer"&TEXT(RANDBETWEEN(1,30),"000"), IF(RAND()<=0.8, "Customer"&TEXT(RANDBETWEEN(31,80),"000"), "Customer"&TEXT(RANDBETWEEN(81,139),"000"))) -> Customer024 | F57: {=INDEX({"Male","Female"}, RANDBETWEEN(1,2))} -> Male | G57: =_xlfn.XLOOKUP(E57,AI$1:AI$139,AF$2:AF$140) -> East | H57: =_xlfn.XLOOKUP(E57,AI$1:AI$139,AJ$1:AJ$139) -> 45182 | I57: =DAY(H57) -> 13 | J57: =TEXT(H57,"mmmm") -> September | K57: =YEAR(H57) -> 2023 | L57: =IF(AND(D57>=10,C57>=24),"Platinum",IF(AND(D57>=7,C57>=18),"Gold",IF(AND(D57>=3,C57>=12),"Silver","Bronze"))) -> Platinum | M57: 57 | N57: Sports | O57: Product 057 | P57: 170 | Q57: 209.1 | R57: 57 | S57: =TEXT(T57,"MMM") -> Apr | T57: 45766 | U57: 3 | V57: 190 | W57: 47 | X57: 1 | Y57: =combined_tbl!$Q57*(1-combined_tbl!$Z57) -> 198.645 | Z57: =IF(combined_tbl!$Q57>=500,0.2, IF(combined_tbl!$Q57>=200,0.05, IF(combined_tbl!$X57>=2,0.05,0))) -> 0.05 | AA57: =combined_tbl!$Y57*combined_tbl!$X57 -> 198.645 | AB57: =(combined_tbl!$Q57*(1+combined_tbl!$Z57)-combined_tbl!$P57)*combined_tbl!$X57 -> 49.555 | AF57: =CHOOSE(RANDBETWEEN(1,4),"West","East","North","South") -> East | AI57: ="Customer"&TEXT(ROW(A57),"000") -> Customer057 | AJ57: =DATE(2023,1,1)+RANDBETWEEN(0,1095) -> 45406
A58: 57 | B58: {=MIN(IF($E:$E=E58,$H:$H))} -> 45812 | C58: =DATEDIF(B58,MAX($H:$H),"m") -> 6 | D58: =COUNTIF(E:E,combined_tbl!$E58) -> 1 | E58: =IF(RAND()<=0.5, "Customer"&TEXT(RANDBETWEEN(1,30),"000"), IF(RAND()<=0.8, "Customer"&TEXT(RANDBETWEEN(31,80),"000"), "Customer"&TEXT(RANDBETWEEN(81,139),"000"))) -> Customer124 | F58: {=INDEX({"Male","Female"}, RANDBETWEEN(1,2))} -> Female | G58: =_xlfn.XLOOKUP(E58,AI$1:AI$139,AF$2:AF$140) -> East | H58: =_xlfn.XLOOKUP(E58,AI$1:AI$139,AJ$1:AJ$139) -> 45812 | I58: =DAY(H58) -> 4 | J58: =TEXT(H58,"mmmm") -> June | K58: =YEAR(H58) -> 2025 | L58: =IF(AND(D58>=10,C58>=24),"Platinum",IF(AND(D58>=7,C58>=18),"Gold",IF(AND(D58>=3,C58>=12),"Silver","Bronze"))) -> Bronze | M58: 58 | N58: Clothing | O58: Product 058 | P58: 127 | Q58: 148.59 | R58: 58 | S58: =TEXT(T58,"MMM") -> Jun | T58: 45080 | U58: 8 | V58: 87 | W58: 29 | X58: 1 | Y58: =combined_tbl!$Q58*(1-combined_tbl!$Z58) -> 148.59 | Z58: =IF(combined_tbl!$Q58>=500,0.2, IF(combined_tbl!$Q58>=200,0.05, IF(combined_tbl!$X58>=2,0.05,0))) -> 0 | AA58: =combined_tbl!$Y58*combined_tbl!$X58 -> 148.59 | AB58: =(combined_tbl!$Q58*(1+combined_tbl!$Z58)-combined_tbl!$P58)*combined_tbl!$X58 -> 21.59 | AF58: =CHOOSE(RANDBETWEEN(1,4),"West","East","North","South") -> West | AI58: ="Customer"&TEXT(ROW(A58),"000") -> Customer058 | AJ58: =DATE(2023,1,1)+RANDBETWEEN(0,1095) -> 45965
A59: 58 | B59: {=MIN(IF($E:$E=E59,$H:$H))} -> 45608 | C59: =DATEDIF(B59,MAX($H:$H),"m") -> 12 | D59: =COUNTIF(E:E,combined_tbl!$E59) -> 5 | E59: =IF(RAND()<=0.5, "Customer"&TEXT(RANDBETWEEN(1,30),"000"), IF(RAND()<=0.8, "Customer"&TEXT(RANDBETWEEN(31,80),"000"), "Customer"&TEXT(RANDBETWEEN(81,139),"000"))) -> Customer041 | F59: {=INDEX({"Male","Female"}, RANDBETWEEN(1,2))} -> Male | G59: =_xlfn.XLOOKUP(E59,AI$1:AI$139,AF$2:AF$140) -> West | H59: =_xlfn.XLOOKUP(E59,AI$1:AI$139,AJ$1:AJ$139) -> 45608 | I59: =DAY(H59) -> 12 | J59: =TEXT(H59,"mmmm") -> November | K59: =YEAR(H59) -> 2024 | L59: =IF(AND(D59>=10,C59>=24),"Platinum",IF(AND(D59>=7,C59>=18),"Gold",IF(AND(D59>=3,C59>=12),"Silver","Bronze"))) -> Silver | M59: 59 | N59: Games | O59: Product 059 | P59: 528 | Q59: 644.16 | R59: 59 | S59: =TEXT(T59,"MMM") -> Jun | T59: 45469 | U59: 6 | V59: 106 | W59: 94 | X59: 1 | Y59: =combined_tbl!$Q59*(1-combined_tbl!$Z59) -> 515.328 | Z59: =IF(combined_tbl!$Q59>=500,0.2, IF(combined_tbl!$Q59>=200,0.05, IF(combined_tbl!$X59>=2,0.05,0))) -> 0.2 | AA59: =combined_tbl!$Y59*combined_tbl!$X59 -> 515.328 | AB59: =(combined_tbl!$Q59*(1+combined_tbl!$Z59)-combined_tbl!$P59)*combined_tbl!$X59 -> 244.992 | AF59: =CHOOSE(RANDBETWEEN(1,4),"West","East","North","South") -> North | AI59: ="Customer"&TEXT(ROW(A59),"000") -> Customer059 | AJ59: =DATE(2023,1,1)+RANDBETWEEN(0,1095) -> 45637
A60: 59 | B60: {=MIN(IF($E:$E=E60,$H:$H))} -> 45812 | C60: =DATEDIF(B60,MAX($H:$H),"m") -> 6 | D60: =COUNTIF(E:E,combined_tbl!$E60) -> 10 | E60: =IF(RAND()<=0.5, "Customer"&TEXT(RANDBETWEEN(1,30),"000"), IF(RAND()<=0.8, "Customer"&TEXT(RANDBETWEEN(31,80),"000"), "Customer"&TEXT(RANDBETWEEN(81,139),"000"))) -> Customer026 | F60: {=INDEX({"Male","Female"}, RANDBETWEEN(1,2))} -> Male | G60: =_xlfn.XLOOKUP(E60,AI$1:AI$139,AF$2:AF$140) -> North | H60: =_xlfn.XLOOKUP(E60,AI$1:AI$139,AJ$1:AJ$139) -> 45812 | I60: =DAY(H60) -> 4 | J60: =TEXT(H60,"mmmm") -> June | K60: =YEAR(H60) -> 2025 | L60: =IF(AND(D60>=10,C60>=24),"Platinum",IF(AND(D60>=7,C60>=18),"Gold",IF(AND(D60>=3,C60>=12),"Silver","Bronze"))) -> Bronze | M60: 60 | N60: Home Appliances | O60: Product 060 | P60: 46 | Q60: 62.1 | R60: 60 | S60: =TEXT(T60,"MMM") -> Mar | T60: 45741 | U60: 2 | V60: 132 | W60: 6 | X60: 2 | Y60: =combined_tbl!$Q60*(1-combined_tbl!$Z60) -> 58.995 | Z60: =IF(combined_tbl!$Q60>=500,0.2, IF(combined_tbl!$Q60>=200,0.05, IF(combined_tbl!$X60>=2,0.05,0))) -> 0.05 | AA60: =combined_tbl!$Y60*combined_tbl!$X60 -> 117.99 | AB60: =(combined_tbl!$Q60*(1+combined_tbl!$Z60)-combined_tbl!$P60)*combined_tbl!$X60 -> 38.41 | AF60: =CHOOSE(RANDBETWEEN(1,4),"West","East","North","South") -> East | AI60: ="Customer"&TEXT(ROW(A60),"000") -> Customer060 | AJ60: =DATE(2023,1,1)+RANDBETWEEN(0,1095) -> 45788
A61: 60 | B61: {=MIN(IF($E:$E=E61,$H:$H))} -> 44960 | C61: =DATEDIF(B61,MAX($H:$H),"m") -> 34 | D61: =COUNTIF(E:E,combined_tbl!$E61) -> 6 | E61: =IF(RAND()<=0.5, "Customer"&TEXT(RANDBETWEEN(1,30),"000"), IF(RAND()<=0.8, "Customer"&TEXT(RANDBETWEEN(31,80),"000"), "Customer"&TEXT(RANDBETWEEN(81,139),"000"))) -> Customer042 | F61: {=INDEX({"Male","Female"}, RANDBETWEEN(1,2))} -> Female | G61: =_xlfn.XLOOKUP(E61,AI$1:AI$139,AF$2:AF$140) -> East | H61: =_xlfn.XLOOKUP(E61,AI$1:AI$139,AJ$1:AJ$139) -> 44960 | I61: =DAY(H61) -> 3 | J61: =TEXT(H61,"mmmm") -> February | K61: =YEAR(H61) -> 2023 | L61: =IF(AND(D61>=10,C61>=24),"Platinum",IF(AND(D61>=7,C61>=18),"Gold",IF(AND(D61>=3,C61>=12),"Silver","Bronze"))) -> Silver | M61: 61 | N61: Groceries | O61: Product 061 | P61: 61 | Q61: 77.47 | R61: 61 | S61: =TEXT(T61,"MMM") -> Nov | T61: 45599 | U61: 7 | V61: 43 | W61: 72 | X61: 1 | Y61: =combined_tbl!$Q61*(1-combined_tbl!$Z61) -> 77.47 | Z61: =IF(combined_tbl!$Q61>=500,0.2, IF(combined_tbl!$Q61>=200,0.05, IF(combined_tbl!$X61>=2,0.05,0))) -> 0 | AA61: =combined_tbl!$Y61*combined_tbl!$X61 -> 77.47 | AB61: =(combined_tbl!$Q61*(1+combined_tbl!$Z61)-combined_tbl!$P61)*combined_tbl!$X61 -> 16.47 | AF61: =CHOOSE(RANDBETWEEN(1,4),"West","East","North","South") -> North | AI61: ="Customer"&TEXT(ROW(A61),"000") -> Customer061 | AJ61: =DATE(2023,1,1)+RANDBETWEEN(0,1095) -> 45395
A62: 61 | B62: {=MIN(IF($E:$E=E62,$H:$H))} -> 45439 | C62: =DATEDIF(B62,MAX($H:$H),"m") -> 18 | D62: =COUNTIF(E:E,combined_tbl!$E62) -> 10 | E62: =IF(RAND()<=0.5, "Customer"&TEXT(RANDBETWEEN(1,30),"000"), IF(RAND()<=0.8, "Customer"&TEXT(RANDBETWEEN(31,80),"000"), "Customer"&TEXT(RANDBETWEEN(81,139),"000"))) -> Customer018 | F62: {=INDEX({"Male","Female"}, RANDBETWEEN(1,2))} -> Male | G62: =_xlfn.XLOOKUP(E62,AI$1:AI$139,AF$2:AF$140) -> East | H62: =_xlfn.XLOOKUP(E62,AI$1:AI$139,AJ$1:AJ$139) -> 45439 | I62: =DAY(H62) -> 27 | J62: =TEXT(H62,"mmmm") -> May | K62: =YEAR(H62) -> 2024 | L62: =IF(AND(D62>=10,C62>=24),"Platinum",IF(AND(D62>=7,C62>=18),"Gold",IF(AND(D62>=3,C62>=12),"Silver","Bronze"))) -> Gold | M62: 62 | N62: Games | O62: Product 062 | P62: 305 | Q62: 445.3 | R62: 62 | S62: =TEXT(T62,"MMM") -> Oct | T62: 45575 | U62: 8 | V62: 47 | W62: 1 | X62: 1 | Y62: =combined_tbl!$Q62*(1-combined_tbl!$Z62) -> 423.035 | Z62: =IF(combined_tbl!$Q62>=500,0.2, IF(combined_tbl!$Q62>=200,0.05, IF(combined_tbl!$X62>=2,0.05,0))) -> 0.05 | AA62: =combined_tbl!$Y62*combined_tbl!$X62 -> 423.035 | AB62: =(combined_tbl!$Q62*(1+combined_tbl!$Z62)-combined_tbl!$P62)*combined_tbl!$X62 -> 162.565 | AF62: =CHOOSE(RANDBETWEEN(1,4),"West","East","North","South") -> West | AI62: ="Customer"&TEXT(ROW(A62),"000") -> Customer062 | AJ62: =DATE(2023,1,1)+RANDBETWEEN(0,1095) -> 45111
A63: 62 | B63: {=MIN(IF($E:$E=E63,$H:$H))} -> 45995 | C63: =DATEDIF(B63,MAX($H:$H),"m") -> 0 | D63: =COUNTIF(E:E,combined_tbl!$E63) -> 8 | E63: =IF(RAND()<=0.5, "Customer"&TEXT(RANDBETWEEN(1,30),"000"), IF(RAND()<=0.8, "Customer"&TEXT(RANDBETWEEN(31,80),"000"), "Customer"&TEXT(RANDBETWEEN(81,139),"000"))) -> Customer013 | F63: {=INDEX({"Male","Female"}, RANDBETWEEN(1,2))} -> Female | G63: =_xlfn.XLOOKUP(E63,AI$1:AI$139,AF$2:AF$140) -> North | H63: =_xlfn.XLOOKUP(E63,AI$1:AI$139,AJ$1:AJ$139) -> 45995 | I63: =DAY(H63) -> 4 | J63: =TEXT(H63,"mmmm") -> December | K63: =YEAR(H63) -> 2025 | L63: =IF(AND(D63>=10,C63>=24),"Platinum",IF(AND(D63>=7,C63>=18),"Gold",IF(AND(D63>=3,C63>=12),"Silver","Bronze"))) -> Bronze | M63: 63 | N63: Jewelry | O63: Product 063 | P63: 190 | Q63: 241.3 | R63: 63 | S63: =TEXT(T63,"MMM") -> Mar | T63: 45000 | U63: 2 | V63: 165 | W63: 70 | X63: 1 | Y63: =combined_tbl!$Q63*(1-combined_tbl!$Z63) -> 229.235 | Z63: =IF(combined_tbl!$Q63>=500,0.2, IF(combined_tbl!$Q63>=200,0.05, IF(combined_tbl!$X63>=2,0.05,0))) -> 0.05 | AA63: =combined_tbl!$Y63*combined_tbl!$X63 -> 229.235 | AB63: =(combined_tbl!$Q63*(1+combined_tbl!$Z63)-combined_tbl!$P63)*combined_tbl!$X63 -> 63.365 | AF63: =CHOOSE(RANDBETWEEN(1,4),"West","East","North","South") -> South | AI63: ="Customer"&TEXT(ROW(A63),"000") -> Customer063 | AJ63: =DATE(2023,1,1)+RANDBETWEEN(0,1095) -> 45307
A64: 63 | B64: {=MIN(IF($E:$E=E64,$H:$H))} -> 45209 | C64: =DATEDIF(B64,MAX($H:$H),"m") -> 25 | D64: =COUNTIF(E:E,combined_tbl!$E64) -> 2 | E64: =IF(RAND()<=0.5, "Customer"&TEXT(RANDBETWEEN(1,30),"000"), IF(RAND()<=0.8, "Customer"&TEXT(RANDBETWEEN(31,80),"000"), "Customer"&TEXT(RANDBETWEEN(81,139),"000"))) -> Customer093 | F64: {=INDEX({"Male","Female"}, RANDBETWEEN(1,2))} -> Male | G64: =_xlfn.XLOOKUP(E64,AI$1:AI$139,AF$2:AF$140) -> North | H64: =_xlfn.XLOOKUP(E64,AI$1:AI$139,AJ$1:AJ$139) -> 45209 | I64: =DAY(H64) -> 10 | J64: =TEXT(H64,"mmmm") -> October | K64: =YEAR(H64) -> 2023 | L64: =IF(AND(D64>=10,C64>=24),"Platinum",IF(AND(D64>=7,C64>=18),"Gold",IF(AND(D64>=3,C64>=12),"Silver","Bronze"))) -> Bronze | M64: 64 | N64: Beauty | O64: Product 064 | P64: 15 | Q64: 17.4 | R64: 64 | S64: =TEXT(T64,"MMM") -> Apr | T64: 45407 | U64: 5 | V64: 101 | W64: 73 | X64: 1 | Y64: =combined_tbl!$Q64*(1-combined_tbl!$Z64) -> 17.4 | Z64: =IF(combined_tbl!$Q64>=500,0.2, IF(combined_tbl!$Q64>=200,0.05, IF(combined_tbl!$X64>=2,0.05,0))) -> 0 | AA64: =combined_tbl!$Y64*combined_tbl!$X64 -> 17.4 | AB64: =(combined_tbl!$Q64*(1+combined_tbl!$Z64)-combined_tbl!$P64)*combined_tbl!$X64 -> 2.4 | AF64: =CHOOSE(RANDBETWEEN(1,4),"West","East","North","South") -> North | AI64: ="Customer"&TEXT(ROW(A64),"000") -> Customer064 | AJ64: =DATE(2023,1,1)+RANDBETWEEN(0,1095) -> 45580
A65: 64 | B65: {=MIN(IF($E:$E=E65,$H:$H))} -> 45182 | C65: =DATEDIF(B65,MAX($H:$H),"m") -> 26 | D65: =COUNTIF(E:E,combined_tbl!$E65) -> 13 | E65: =IF(RAND()<=0.5, "Customer"&TEXT(RANDBETWEEN(1,30),"000"), IF(RAND()<=0.8, "Customer"&TEXT(RANDBETWEEN(31,80),"000"), "Customer"&TEXT(RANDBETWEEN(81,139),"000"))) -> Customer024 | F65: {=INDEX({"Male","Female"}, RANDBETWEEN(1,2))} -> Male | G65: =_xlfn.XLOOKUP(E65,AI$1:AI$139,AF$2:AF$140) -> East | H65: =_xlfn.XLOOKUP(E65,AI$1:AI$139,AJ$1:AJ$139) -> 45182 | I65: =DAY(H65) -> 13 | J65: =TEXT(H65,"mmmm") -> September | K65: =YEAR(H65) -> 2023 | L65: =IF(AND(D65>=10,C65>=24),"Platinum",IF(AND(D65>=7,C65>=18),"Gold",IF(AND(D65>=3,C65>=12),"Silver","Bronze"))) -> Platinum | M65: 65 | N65: Toys | O65: Product 065 | P65: 148 | Q65: 219.04 | R65: 65 | S65: =TEXT(T65,"MMM") -> Apr | T65: 45392 | U65: 2 | V65: 103 | W65: 57 | X65: 4 | Y65: =combined_tbl!$Q65*(1-combined_tbl!$Z65) -> 208.088 | Z65: =IF(combined_tbl!$Q65>=500,0.2, IF(combined_tbl!$Q65>=200,0.05, IF(combined_tbl!$X65>=2,0.05,0))) -> 0.05 | AA65: =combined_tbl!$Y65*combined_tbl!$X65 -> 832.352 | AB65: =(combined_tbl!$Q65*(1+combined_tbl!$Z65)-combined_tbl!$P65)*combined_tbl!$X65 -> 327.968 | AF65: =CHOOSE(RANDBETWEEN(1,4),"West","East","North","South") -> East | AI65: ="Customer"&TEXT(ROW(A65),"000") -> Customer065 | AJ65: =DATE(2023,1,1)+RANDBETWEEN(0,1095) -> 44993
A66: 65 | B66: {=MIN(IF($E:$E=E66,$H:$H))} -> 44992 | C66: =DATEDIF(B66,MAX($H:$H),"m") -> 32 | D66: =COUNTIF(E:E,combined_tbl!$E66) -> 8 | E66: =IF(RAND()<=0.5, "Customer"&TEXT(RANDBETWEEN(1,30),"000"), IF(RAND()<=0.8, "Customer"&TEXT(RANDBETWEEN(31,80),"000"), "Customer"&TEXT(RANDBETWEEN(81,139),"000"))) -> Customer020 | F66: {=INDEX({"Male","Female"}, RANDBETWEEN(1,2))} -> Female | G66: =_xlfn.XLOOKUP(E66,AI$1:AI$139,AF$2:AF$140) -> South | H66: =_xlfn.XLOOKUP(E66,AI$1:AI$139,AJ$1:AJ$139) -> 44992 | I66: =DAY(H66) -> 7 | J66: =TEXT(H66,"mmmm") -> March | K66: =YEAR(H66) -> 2023 | L66: =IF(AND(D66>=10,C66>=24),"Platinum",IF(AND(D66>=7,C66>=18),"Gold",IF(AND(D66>=3,C66>=12),"Silver","Bronze"))) -> Gold | M66: 66 | N66: Groceries | O66: Product 066 | P66: 15 | Q66: 17.85 | R66: 66 | S66: =TEXT(T66,"MMM") -> Jun | T66: 45815 | U66: 2 | V66: 27 | W66: 30 | X66: 1 | Y66: =combined_tbl!$Q66*(1-combined_tbl!$Z66) -> 17.85 | Z66: =IF(combined_tbl!$Q66>=500,0.2, IF(combined_tbl!$Q66>=200,0.05, IF(combined_tbl!$X66>=2,0.05,0))) -> 0 | AA66: =combined_tbl!$Y66*combined_tbl!$X66 -> 17.85 | AB66: =(combined_tbl!$Q66*(1+combined_tbl!$Z66)-combined_tbl!$P66)*combined_tbl!$X66 -> 2.85 | AF66: =CHOOSE(RANDBETWEEN(1,4),"West","East","North","South") -> West | AI66: ="Customer"&TEXT(ROW(A66),"000") -> Customer066 | AJ66: =DATE(2023,1,1)+RANDBETWEEN(0,1095) -> 45433
... A139: 138 | B139: {=MIN(IF($E:$E=E139,$H:$H))} -> 45896 | C139: =DATEDIF(B139,MAX($H:$H),"m") -> 3 | D139: =COUNTIF(E:E,combined_tbl!$E139) -> 10 | E139: =IF(RAND()<=0.5, "Customer"&TEXT(RANDBETWEEN(1,30),"000"), IF(RAND()<=0.8, "Customer"&TEXT(RANDBETWEEN(31,80),"000"), "Customer"&TEXT(RANDBETWEEN(81,139),"000"))) -> Customer004 | F139: {=INDEX({"Male","Female"}, RANDBETWEEN(1,2))} -> Male | G139: =_xlfn.XLOOKUP(E139,AI$1:AI$139,AF$2:AF$140) -> West | H139: =_xlfn.XLOOKUP(E139,AI$1:AI$139,AJ$1:AJ$139) -> 45896 | I139: =DAY(H139) -> 27 | J139: =TEXT(H139,"mmmm") -> August | K139: =YEAR(H139) -> 2025 | L139: =IF(AND(D139>=10,C139>=24),"Platinum",IF(AND(D139>=7,C139>=18),"Gold",IF(AND(D139>=3,C139>=12),"Silver","Bronze"))) -> Bronze | M139: 139 | N139: Beauty | O139: Product 139 | P139: 99 | Q139: 132.66 | R139: 139 | S139: =TEXT(T139,"MMM") -> Sep | T139: 45177 | U139: 8 | V139: 85 | W139: 17 | X139: 1 | Y139: =combined_tbl!$Q139*(1-combined_tbl!$Z139) -> 132.66 | Z139: =IF(combined_tbl!$Q139>=500,0.2, IF(combined_tbl!$Q139>=200,0.05, IF(combined_tbl!$X139>=2,0.05,0))) -> 0 | AA139: =combined_tbl!$Y139*combined_tbl!$X139 -> 132.66 | AB139: =(combined_tbl!$Q139*(1+combined_tbl!$Z139)-combined_tbl!$P139)*combined_tbl!$X139 -> 33.66 | AF139: =CHOOSE(RANDBETWEEN(1,4),"West","East","North","South") -> West | AI139: ="Customer"&TEXT(ROW(A139),"000") -> Customer139 | AJ139: =DATE(2023,1,1)+RANDBETWEEN(0,1095) -> 45474
A140: 139 | B140: {=MIN(IF($E:$E=E140,$H:$H))} -> 45492 | C140: =DATEDIF(B140,MAX($H:$H),"m") -> 16 | D140: =COUNTIF(E:E,combined_tbl!$E140) -> 5 | E140: =IF(RAND()<=0.5, "Customer"&TEXT(RANDBETWEEN(1,30),"000"), IF(RAND()<=0.8, "Customer"&TEXT(RANDBETWEEN(31,80),"000"), "Customer"&TEXT(RANDBETWEEN(81,139),"000"))) -> Customer047 | F140: {=INDEX({"Male","Female"}, RANDBETWEEN(1,2))} -> Female | G140: =_xlfn.XLOOKUP(E140,AI$1:AI$139,AF$2:AF$140) -> North | H140: =_xlfn.XLOOKUP(E140,AI$1:AI$139,AJ$1:AJ$139) -> 45492 | I140: =DAY(H140) -> 19 | J140: =TEXT(H140,"mmmm") -> July | K140: =YEAR(H140) -> 2024 | L140: =IF(AND(D140>=10,C140>=24),"Platinum",IF(AND(D140>=7,C140>=18),"Gold",IF(AND(D140>=3,C140>=12),"Silver","Bronze"))) -> Silver | M140: 140 | N140: Toys | O140: Product 140 | P140: 180 | Q140: 223.2 | R140: 140 | S140: =TEXT(T140,"MMM") -> Jul | T140: 45114 | U140: 4 | V140: 218 | W140: 1 | X140: 1 | Y140: =combined_tbl!$Q140*(1-combined_tbl!$Z140) -> 212.04 | Z140: =IF(combined_tbl!$Q140>=500,0.2, IF(combined_tbl!$Q140>=200,0.05, IF(combined_tbl!$X140>=2,0.05,0))) -> 0.05 | AA140: =combined_tbl!$Y140*combined_tbl!$X140 -> 212.04 | AB140: =(combined_tbl!$Q140*(1+combined_tbl!$Z140)-combined_tbl!$P140)*combined_tbl!$X140 -> 54.36
A141: 140 | B141: {=MIN(IF($E:$E=E141,$H:$H))} -> 45014 | C141: =DATEDIF(B141,MAX($H:$H),"m") -> 32 | D141: =COUNTIF(E:E,combined_tbl!$E141) -> 10 | E141: =IF(RAND()<=0.5, "Customer"&TEXT(RANDBETWEEN(1,30),"000"), IF(RAND()<=0.8, "Customer"&TEXT(RANDBETWEEN(31,80),"000"), "Customer"&TEXT(RANDBETWEEN(81,139),"000"))) -> Customer022 | F141: {=INDEX({"Male","Female"}, RANDBETWEEN(1,2))} -> Female | G141: =_xlfn.XLOOKUP(E141,AI$1:AI$139,AF$2:AF$140) -> South | H141: =_xlfn.XLOOKUP(E141,AI$1:AI$139,AJ$1:AJ$139) -> 45014 | I141: =DAY(H141) -> 29 | J141: =TEXT(H141,"mmmm") -> March | K141: =YEAR(H141) -> 2023 | L141: =IF(AND(D141>=10,C141>=24),"Platinum",IF(AND(D141>=7,C141>=18),"Gold",IF(AND(D141>=3,C141>=12),"Silver","Bronze"))) -> Platinum | M141: 141 | N141: Beauty | O141: Product 141 | P141: 59 | Q141: 67.85 | R141: 141 | S141: =TEXT(T141,"MMM") -> Feb | T141: 44970 | U141: 1 | V141: 10 | W141: 2 | X141: 1 | Y141: =combined_tbl!$Q141*(1-combined_tbl!$Z141) -> 67.85 | Z141: =IF(combined_tbl!$Q141>=500,0.2, IF(combined_tbl!$Q141>=200,0.05, IF(combined_tbl!$X141>=2,0.05,0))) -> 0 | AA141: =combined_tbl!$Y141*combined_tbl!$X141 -> 67.85 | AB141: =(combined_tbl!$Q141*(1+combined_tbl!$Z141)-combined_tbl!$P141)*combined_tbl!$X141 -> 8.85
A142: 141 | B142: {=MIN(IF($E:$E=E142,$H:$H))} -> 45582 | C142: =DATEDIF(B142,MAX($H:$H),"m") -> 13 | D142: =COUNTIF(E:E,combined_tbl!$E142) -> 11 | E142: =IF(RAND()<=0.5, "Customer"&TEXT(RANDBETWEEN(1,30),"000"), IF(RAND()<=0.8, "Customer"&TEXT(RANDBETWEEN(31,80),"000"), "Customer"&TEXT(RANDBETWEEN(81,139),"000"))) -> Customer002 | F142: {=INDEX({"Male","Female"}, RANDBETWEEN(1,2))} -> Male | G142: =_xlfn.XLOOKUP(E142,AI$1:AI$139,AF$2:AF$140) -> East | H142: =_xlfn.XLOOKUP(E142,AI$1:AI$139,AJ$1:AJ$139) -> 45582 | I142: =DAY(H142) -> 17 | J142: =TEXT(H142,"mmmm") -> October | K142: =YEAR(H142) -> 2024 | L142: =IF(AND(D142>=10,C142>=24),"Platinum",IF(AND(D142>=7,C142>=18),"Gold",IF(AND(D142>=3,C142>=12),"Silver","Bronze"))) -> Silver | M142: 142 | N142: Groceries | O142: Product 142 | P142: 53 | Q142: 67.84 | R142: 142 | S142: =TEXT(T142,"MMM") -> Nov | T142: 45610 | U142: 4 | V142: 119 | W142: 62 | X142: 2 | Y142: =combined_tbl!$Q142*(1-combined_tbl!$Z142) -> 64.448 | Z142: =IF(combined_tbl!$Q142>=500,0.2, IF(combined_tbl!$Q142>=200,0.05, IF(combined_tbl!$X142>=2,0.05,0))) -> 0.05 | AA142: =combined_tbl!$Y142*combined_tbl!$X142 -> 128.896 | AB142: =(combined_tbl!$Q142*(1+combined_tbl!$Z142)-combined_tbl!$P142)*combined_tbl!$X142 -> 36.464
